<?xml version="1.0" ?>
<!-- =================================================================================== -->
<!-- |    This document was autogenerated by xacro from ddrive.urdf.xacro              | -->
<!-- |    EDITING THIS FILE BY HAND IS NOT RECOMMENDED                                 | -->
<!-- =================================================================================== -->
<robot name="ddrive">
  <mujoco>
      <compiler meshdir="../meshes/" balanceinertia="true"/>
  </mujoco>
  <link name="top_caster">
    <inertial>
      <mass value="0.1"/>
      <inertia ixx="0.0005833333333333334" ixy="0.0" ixz="0.0" iyy="0.0005833333333333334" iyz="0.0" izz="0.00012500000000000003"/>
    </inertial>
    <visual>
      <origin xyz="0 0 0"/>
      <geometry name="top_caster">
        <cylinder length="0.05" radius="0.05"/>
      </geometry>
      <material name="well">
        <color rgba="0 1 1 1"/>
      </material>
    </visual>
    <collision>
      <origin xyz="0 0 0"/>
      <geometry name="top_caster_col">
        <cylinder length="0.05" radius="0.05"/>
      </geometry>
    </collision>
  </link>
  <link name="bot_caster">
    <inertial>
      <mass value="0.1"/>
      <inertia ixx="0.0005833333333333334" ixy="0.0" ixz="0.0" iyy="0.0005833333333333334" iyz="0.0" izz="0.00012500000000000003"/>
    </inertial>
    <visual>
      <origin xyz="0 0 0"/>
      <geometry name="bot_caster">
        <cylinder length="0.05" radius="0.05"/>
      </geometry>
      <material name="bot_caster">
        <color rgba="0 1 1 1"/>
      </material>
    </visual>
    <collision>
      <origin xyz="0 0 0"/>
      <geometry name="bot_caster_col">
        <cylinder length="0.05" radius="0.05"/>
      </geometry>
    </collision>
  </link>
  <!-- The base of the robot -->
  <link name="base_link">
    <inertial>
      <mass value="1"/>
      <inertia ixx="0.03333333333333333" ixy="0.0" ixz="0.0" iyy="0.12333333333333334" iyz="0.0" izz="0.11333333333333331"/>
    </inertial>
    <visual>
      <origin xyz="0 0 0"/>
      <geometry name="base_link">
        <box size="1.0 0.6 0.2"/>
      </geometry>
      <material name="base_link">
        <color rgba="1 0 0 1"/>
      </material>
    </visual>
    <collision>
      <origin xyz="0 0 0"/>
      <geometry name="base_link_col">
        <box size="1.0 0.6 0.2"/>
      </geometry>
    </collision>
  </link>
  <!-- Back left wheel of robot -->
  <link name="blWheel">
    <inertial>
      <mass value="1"/>
      <inertia ixx="0.010208333333333335" ixy="0.0" ixz="0.0" iyy="0.010208333333333335" iyz="0.0" izz="0.020000000000000004"/>
    </inertial>
    <visual>
      <origin xyz="0 0 0"/>
      <geometry name="blWheel">
        <cylinder length="0.1" radius="0.2"/>
      </geometry>
      <material name="blWheel">
        <color rgba="1 1 1 1"/>
      </material>
    </visual>
    <collision>
      <origin xyz="0 0 0"/>
      <geometry name="blWheel_col">
        <cylinder length="0.1" radius="0.2"/>
      </geometry>
    </collision>
  </link>
  <!-- Back right wheel of robot -->
  <link name="brWheel">
    <inertial>
      <mass value="1"/>
      <inertia ixx="0.010208333333333335" ixy="0.0" ixz="0.0" iyy="0.010208333333333335" iyz="0.0" izz="0.020000000000000004"/>
    </inertial>
    <visual>
      <origin xyz="0 0 0"/>
      <geometry name="brWheel">
        <cylinder length="0.1" radius="0.2"/>
      </geometry>
      <material name="brWheel">
        <color rgba="1 1 1 1"/>
      </material>
    </visual>
    <collision>
      <origin xyz="0 0 0"/>
      <geometry name="brWheel_col">
        <cylinder length="0.1" radius="0.2"/>
      </geometry>
    </collision>
  </link>
  <!-- The block of the robot that the casters connect to -->
  <link name="block">
    <inertial>
      <mass value="0.2"/>
      <inertia ixx="0.0016666666666666668" ixy="0.0" ixz="0.0" iyy="0.0016666666666666668" iyz="0.0" izz="0.0003333333333333334"/>
    </inertial>
    <visual>
      <origin xyz="0 0 0"/>
      <geometry name="block">
        <box size="0.1 0.1 0.3"/>
      </geometry>
      <material name="block">
        <color rgba="0 1 0 1"/>
      </material>
    </visual>
    <collision>
      <origin xyz="0 0 0"/>
      <geometry name="block_col">
        <box size="0.1 0.1 0.3"/>
      </geometry>
    </collision>
  </link>
  <!-- Joint between base and back left wheel -->
  <joint name="base-blWheel" type="continuous">
    <origin rpy="1.5707963267948966 0.0 0.0" xyz="-0.5 0.35 0"/>
    <parent link="base_link"/>
    <child link="blWheel"/>
    <axis xyz="0.0 0.0 -1.0"/>
  </joint>
  <!-- Joint between base and back right wheel -->
  <joint name="base-brWheel" type="continuous">
    <origin rpy="-1.5707963267948966 0.0 0.0" xyz="-0.5 -0.35 0"/>
    <parent link="base_link"/>
    <child link="brWheel"/>
    <axis xyz="0.0 0.0 1.0"/>
  </joint>
  <!-- Joint between block and base_link -->
  <joint name="base_link-block" type="fixed">
    <origin rpy="0.0 0.0 0.0" xyz="0.4 0.0 0.0"/>
    <parent link="base_link"/>
    <child link="block"/>
    <axis xyz="0.0 0.0 1.0"/>
  </joint>
  <!-- Joint between block and front top wheel -->
  <joint name="block-top_caster" type="continuous">
    <origin rpy="-1.5707963267948966 0.0 0.0" xyz="0 0 0.15"/>
    <parent link="block"/>
    <child link="top_caster"/>
    <axis xyz="0.0 0.0 -1.0"/>
  </joint>
  <!-- Joint between block and front bottom wheel -->
  <joint name="block-bot_caster" type="continuous">
    <origin rpy="-1.5707963267948966 0.0 0.0" xyz="0 0 -0.15"/>
    <parent link="block"/>
    <child link="bot_caster"/>
    <axis xyz="0.0 0.0 1.0"/>
  </joint>
</robot>
