<?xml version="1.0"?>
<robot name="ddrive" xmlns:xacro="http://www.ros.org/wiki/xacro">

    <!-- Macro for the front wheels -->
    <xacro:macro name="front_wheel" params="name radius">
        <link name="${name}">
            <inertial>
                <mass value="0.1" />
                <inertia
                ixx="${(1/12)*0.1*(3*radius**2 + 0.25**2)}"
                ixy="0.0"
                ixz="0.0"
                iyy="${(1/12)*0.1*(3*radius**2 + 0.25**2)}"
                iyz="0.0"
                izz="${0.5*0.1*radius**2}"
                />
            </inertial>
            <visual>
                <origin xyz="0 0 0" />
                <geometry>
                    <cylinder length="0.05" radius="${radius}" />
                </geometry>
                <material name="">
                    <color rgba="0 1 1 1"/>  
                </material>
            </visual>
            <collision>
                <origin xyz="0 0 0" />
                <geometry>
                    <cylinder length="0.05" radius="${radius}" />
                </geometry>
            </collision>
        </link>
    </xacro:macro>

    <!-- Font wheels of robot -->
    <xacro:front_wheel name="top_caster" radius="0.05"/>
    <xacro:front_wheel name="bot_caster" radius="0.05"/>

    <!-- The base of the robot -->
    <link name="base_link">
        <inertial>
            <mass value="1" />
            <inertia
            ixx="${(1/12)*1*(0.6**2 + 0.2**2)}"
            ixy="0.0"
            ixz="0.0"
            iyy="${(1/12)*1*(1.0**2) + 0.2**2}"
            iyz="0.0"
            izz="${(1/12)*1*(0.6**2 + 1.0**2)}"
            />
        </inertial>
        <visual>
            <origin xyz="0 0 0" />
            <geometry>
                <box size="1.0 0.6 0.2" />
            </geometry>
            <material name="">
                <color rgba="1 0 0 1" />
            </material>
        </visual>
        <collision>
            <origin xyz="0 0 0" />
            <geometry>
                <box size="1.0 0.6 0.2" />
            </geometry>
        </collision>
    </link>

    <!-- Back left wheel of robot -->
    <link name="blWheel">
        <inertial>
            <mass value="1" />
            <inertia
            ixx="${(1/12)*1*(3*0.2**2 + 0.05**2)}"
            ixy="0.0"
            ixz="0.0"
            iyy="${(1/12)*1*(3*0.2**2 + 0.05**2)}"
            iyz="0.0"
            izz="${0.5*1*0.2**2}"
            />
        </inertial>
        <visual>
            <origin xyz="0 0 0" />
            <geometry>
                <cylinder radius="0.2" length="0.1" />
            </geometry>
            <material name="">
                <color rgba="1 1 1 1" />
            </material>
        </visual>
        <collision>
            <origin xyz="0 0 0" />
            <geometry>
                <cylinder radius="0.2" length="0.1" />
            </geometry>
        </collision>
    </link>

    <!-- Back right wheel of robot -->
    <link name="brWheel">
        <inertial>
            <mass value="1" />
            <inertia
            ixx="${(1/12)*1*(3*0.2**2 + 0.05**2)}"
            ixy="0.0"
            ixz="0.0"
            iyy="${(1/12)*1*(3*0.2**2 + 0.05**2)}"
            iyz="0.0"
            izz="${0.5*1*0.2**2}"
            />
        </inertial>
        <visual>
            <origin xyz="0 0 0" />
            <geometry>
                <cylinder radius="0.2" length="0.1" />
            </geometry>
            <material name="">
                <color rgba="1 1 1 1" />
            </material>
        </visual>
        <collision>
            <origin xyz="0 0 0" />
            <geometry>
                <cylinder radius="0.2" length="0.1" />
            </geometry>
        </collision>
    </link>

    <!-- The block of the robot that the casters connect to -->
    <link name="block">
        <inertial>
            <mass value="0.2" />
            <inertia
            ixx="${(1/12)*0.2*(0.3**2 + 0.1**2)}"
            ixy="0.0"
            ixz="0.0"
            iyy="${(1/12)*0.2*(0.1**2 + 0.3**2)}"
            iyz="0.0"
            izz="${(1/12)*0.2*(0.1**2 + 0.1**2)}"
            />
        </inertial>
        <visual>
            <origin xyz="0 0 0" />
            <geometry>
                <box size="0.1 0.1 0.3" />
            </geometry>
            <material name="">
                <color rgba="0 1 0 1" />
            </material>
        </visual>
        <collision>
            <origin xyz="0 0 0" />
            <geometry>
                <box size="0.1 0.1 0.3" />
            </geometry>
        </collision>
    </link>

    <!-- Joint between base and back left wheel -->
    <joint name="base-blWheel" type="continuous">
        <origin xyz="${-1.0/2} 0.35 0" rpy="${radians(90.0)} 0.0 0.0" />
        <parent link="base_link"/>
        <child link="blWheel"/>
        <axis xyz="0.0 0.0 -1.0"/>
    </joint>

    <!-- Joint between base and back right wheel -->
    <joint name="base-brWheel" type="continuous">
        <origin xyz="${-1.0/2} -0.35 0" rpy="${radians(-90.0)} 0.0 0.0" />
        <parent link="base_link"/>
        <child link="brWheel"/>
        <axis xyz="0.0 0.0 1.0"/>
    </joint>

    <!-- Joint between block and base_link -->
    <joint name="base_link-block" type="fixed">
        <origin xyz="${2*1.0/5} 0.0 0.0" rpy="0.0 0.0 0.0" />
        <parent link="base_link"/>
        <child link="block"/>
        <axis xyz="0.0 0.0 1.0"/>
    </joint>

    <!-- Joint between block and front top wheel -->
    <joint name="block-top_caster" type="continuous">
        <origin xyz="0 0 0.15" rpy="${radians(-90.0)} 0.0 0.0" />
        <parent link="block"/>
        <child link="top_caster"/>
        <axis xyz="0.0 0.0 -1.0"/>
    </joint>

    <!-- Joint between block and front bottom wheel -->
    <joint name="block-bot_caster" type="continuous">
        <origin xyz="0 0 -0.15" rpy="${radians(-90.0)} 0.0 0.0" />
        <parent link="block"/>
        <child link="bot_caster"/>
        <axis xyz="0.0 0.0 1.0"/>
    </joint>
</robot>