<mujoco model="ddrive">
  <compiler angle="radian" meshdir="../meshes/"/>

  <asset>
    <material name="grid" texture="grid" texrepeat="1 1" texuniform="true" reflectance=".2"/>
    <texture name="grid" type="2d" builtin="checker" width="512" height="512" rgb1=".1 .2 .3" rgb2=".2 .3 .4"/>
  </asset>

  <default>
    <joint damping=".003" actuatorfrcrange="-1 1"/>
  </default>

  <worldbody>
    <geom type="plane" size="3 3 .01" pos="0.0 0.0 -0.2" material="grid"/>
    <body name="car" pos="0.0 0.0 0.0">
      <freejoint/>
      <geom size="0.5 0.3 0.1" type="box" rgba="1 0 0 1"/>
      <geom size="0.05 0.05 0.15" pos="0.4 0 0" type="box" rgba="0 1 0 1"/>
      <body name="blWheel" pos="-0.5 0.35 0" quat="0.707107 0.707107 0 0">
        <joint name="base-blWheel" pos="0 0 0" axis="0 0 -1"/>
        <geom size="0.2 0.05" type="cylinder" rgba="1 1 1 1"/>
      </body>
      <body name="brWheel" pos="-0.5 -0.35 0" quat="0.707107 -0.707107 0 0">
        <joint name="base-brWheel" pos="0 0 0" axis="0 0 1"/>
        <geom size="0.2 0.05" type="cylinder" rgba="1 1 1 1"/>
      </body>
      <body name="top_caster" pos="0.4 0 0.15" quat="0.707107 -0.707107 0 0">
        <joint name="block-top_caster" pos="0 0 0" axis="0 0 -1"/>
        <geom size="0.05 0.025" type="cylinder" rgba="0 1 1 1"/>
      </body>
      <body name="bot_caster" pos="0.4 0 -0.15" quat="0.707107 -0.707107 0 0">
        <joint name="block-bot_caster" pos="0 0 0" axis="0 0 1"/>
        <geom size="0.05 0.025" type="cylinder" rgba="0 1 1 1"/>
      </body>
    </body>
  </worldbody>

  <tendon>
    <fixed name="forward">
      <joint joint="base-blWheel" coef="2000"/>
      <joint joint="base-brWheel" coef="2000"/>
      <joint joint="block-bot_caster" coef="200"/>
    </fixed>
  </tendon>

  <actuator>
    <motor name="forward" tendon="forward" ctrlrange="-1 1"/>
  </actuator>

  <sensor>
    <jointactuatorfrc name="right" joint="base-brWheel"/>
    <jointactuatorfrc name="left" joint="base-blWheel"/>
  </sensor>
</mujoco>
