<mujoco model="unnamed_model">
  <option timestep="0.01"/>
  <visual>
    <headlight ambient="0.5 0.5 0.5"/>
  </visual>
  <default>
    <default class="/"/>
  </default>
  <worldbody>
    <light name="//unnamed_light_0" class="/" pos="0 0 5" dir="0 0 -1" diffuse="0.5 0.5 0.5"/>
    <geom name="//unnamed_geom_0" class="/" type="plane" size="25 25 0.01"/>
    <body name="abdomen" pos="0 0 1">
      <joint name="//unnamed_joint_0" class="/" type="free"/>
      <geom name="//unnamed_geom_1" class="/" type="ellipsoid" size="1 0.29999999999999999 0.29999999999999999" rgba="1 0 0 1" pos="0 0 0"/>
      <body name="leftLeg0" pos="-0.59999999999999998 0.40000000000000002 -0.29999999999999999">
        <geom name="//unnamed_geom_2" class="/" type="ellipsoid" size="0.10000000000000001 0.10000000000000001 0.40000000000000002" rgba="0 1 0 1"/>
        <joint name="leftLeg1Joint" class="/" type="hinge" pos="0 0.29999999999999999 0.29999999999999999" axis="0 1 0" limited="true" range="-270 270"/>
      </body>
      <body name="rightLeg0" pos="-0.59999999999999998 -0.40000000000000002 -0.29999999999999999">
        <geom name="//unnamed_geom_3" class="/" type="ellipsoid" size="0.10000000000000001 0.10000000000000001 0.40000000000000002" rgba="0 1 0 1"/>
        <joint name="rightLeg1Joint" class="/" type="hinge" pos="0 -0.29999999999999999 0.29999999999999999" axis="0 1 0" range="-360 360"/>
      </body>
      <body name="leftLeg1" pos="-0.19999999999999996 0.40000000000000002 -0.29999999999999999">
        <geom name="//unnamed_geom_4" class="/" type="ellipsoid" size="0.10000000000000001 0.10000000000000001 0.40000000000000002" rgba="0 1 0 1"/>
        <joint name="leftLeg2Joint" class="/" type="hinge" pos="0 0.29999999999999999 0.29999999999999999" axis="0 1 0" limited="true" range="-270 270"/>
      </body>
      <body name="rightLeg1" pos="-0.19999999999999996 -0.40000000000000002 -0.29999999999999999">
        <geom name="//unnamed_geom_5" class="/" type="ellipsoid" size="0.10000000000000001 0.10000000000000001 0.40000000000000002" rgba="0 1 0 1"/>
        <joint name="rightLeg2Joint" class="/" type="hinge" pos="0 -0.29999999999999999 0.29999999999999999" axis="0 1 0" range="-360 360"/>
      </body>
      <body name="leftLeg2" pos="0.20000000000000018 0.40000000000000002 -0.29999999999999999">
        <geom name="//unnamed_geom_6" class="/" type="ellipsoid" size="0.10000000000000001 0.10000000000000001 0.40000000000000002" rgba="0 1 0 1"/>
        <joint name="leftLeg3Joint" class="/" type="hinge" pos="0 0.29999999999999999 0.29999999999999999" axis="0 1 0" limited="true" range="-270 270"/>
      </body>
      <body name="rightLeg2" pos="0.20000000000000018 -0.40000000000000002 -0.29999999999999999">
        <geom name="//unnamed_geom_7" class="/" type="ellipsoid" size="0.10000000000000001 0.10000000000000001 0.40000000000000002" rgba="0 1 0 1"/>
        <joint name="rightLeg3Joint" class="/" type="hinge" pos="0 -0.29999999999999999 0.29999999999999999" axis="0 1 0" range="-360 360"/>
      </body>
      <body name="leftLeg3" pos="0.60000000000000009 0.40000000000000002 -0.29999999999999999">
        <geom name="//unnamed_geom_8" class="/" type="ellipsoid" size="0.10000000000000001 0.10000000000000001 0.40000000000000002" rgba="0 1 0 1"/>
        <joint name="leftLeg4Joint" class="/" type="hinge" pos="0 0.29999999999999999 0.29999999999999999" axis="0 1 0" limited="true" range="-270 270"/>
      </body>
      <body name="rightLeg3" pos="0.60000000000000009 -0.40000000000000002 -0.29999999999999999">
        <geom name="//unnamed_geom_9" class="/" type="ellipsoid" size="0.10000000000000001 0.10000000000000001 0.40000000000000002" rgba="0 1 0 1"/>
        <joint name="rightLeg4Joint" class="/" type="hinge" pos="0 -0.29999999999999999 0.29999999999999999" axis="0 1 0" range="-360 360"/>
      </body>
    </body>
  </worldbody>
  <actuator>
    <motor name="leftMotor1" class="/" ctrllimited="true" ctrlrange="-90 90" gear="5" joint="leftLeg1Joint"/>
    <motor name="rightMotor1" class="/" ctrllimited="true" ctrlrange="-90 90" gear="5" joint="rightLeg1Joint"/>
    <motor name="leftMotor2" class="/" ctrllimited="true" ctrlrange="-90 90" gear="5" joint="leftLeg2Joint"/>
    <motor name="rightMotor2" class="/" ctrllimited="true" ctrlrange="-90 90" gear="5" joint="rightLeg2Joint"/>
    <motor name="leftMotor3" class="/" ctrllimited="true" ctrlrange="-90 90" gear="5" joint="leftLeg3Joint"/>
    <motor name="rightMotor3" class="/" ctrllimited="true" ctrlrange="-90 90" gear="5" joint="rightLeg3Joint"/>
    <motor name="leftMotor4" class="/" ctrllimited="true" ctrlrange="-90 90" gear="5" joint="leftLeg4Joint"/>
    <motor name="rightMotor4" class="/" ctrllimited="true" ctrlrange="-90 90" gear="5" joint="rightLeg4Joint"/>
  </actuator>
</mujoco>
